Workbook

Sheet Times City
A3: Week 4 | C3: Day | D3: Mon | G3: Tue | J3: Wed | M3: Thu | P3: Fri | S3: Sat | V3: Sun
C4: ITEM | D4: Hour | E4: Total Hr | F4: Salary/hr | G4: Hour | H4: Total Hr | I4: Salary/hr | J4: Hour | K4: Total Hr | L4: Salary/hr | M4: Hour | N4: Total Hr | O4: Salary/hr | P4: Hour | Q4: Total Hr | R4: Salary/hr | S4: Hour | T4: Total Hr | U4: Salary/hr | V4: Hour | W4: Total Hr | X4: Salary/hr
A5: TIMES CITY | B5: Morning | C5: Mngt | D5: 8 | E5: =8 -> 8 | F5: =E5*G18 -> 307692.31 | G5: 8 | H5: =8 -> 8 | I5: =H5*G18 -> 307692.31 | J5: 8 | K5: =8 -> 8 | L5: =K5*G18 -> 307692.31 | M5: 8 | N5: =8 -> 8 | O5: =N5*G18 -> 307692.31 | P5: 16 | Q5: =P5 -> 16 | R5: =Q5*G18 -> 615384.62 | S5: 16 | T5: =S5 -> 16 | U5: =T5*G18 -> 615384.62 | V5: 16 | W5: =V5 -> 16 | X5: =W5*G18 -> 615384.62
C6: FOH | D6: 15 | E6: =D6+D7 -> 35 | F6: =E6*G22 -> 735000 | G6: 15 | H6: =G6+G7 -> 35 | I6: =H6*G22 -> 735000 | J6: 15 | K6: =J6+J7 -> 35 | L6: =K6*G22 -> 735000 | M6: 15 | N6: =M6+M7 -> 35 | O6: =N6*G22 -> 735000 | P6: 16 | Q6: =P6+P7 -> 36 | R6: =Q6*G22 -> 756000 | S6: 35 | T6: =S6+S7 -> 70 | U6: =T6*G22 -> 1470000 | V6: 35 | W6: =V6+V7 -> 70 | X6: =W6*G22 -> 1470000
C7: BOH | D7: 20 | G7: 20 | J7: 20 | M7: 20 | P7: 20 | S7: 35 | V7: 35
B9: Afternoon | C9: Mngt | D9: 16 | E9: =D9 -> 16 | F9: =E9*G18 -> 615384.62 | G9: 16 | H9: =G9 -> 16 | I9: =H9*G18 -> 615384.62 | J9: 16 | K9: =J9 -> 16 | L9: =K9*G18 -> 615384.62 | M9: 16 | N9: =M9 -> 16 | O9: =N9*G18 -> 615384.62 | P9: 16 | Q9: =P9 -> 16 | R9: =Q9*G18 -> 615384.62 | S9: 16 | T9: =S9 -> 16 | U9: =T9*G18 -> 615384.62 | V9: 16 | W9: =V9 -> 16 | X9: =W9*G18 -> 615384.62
C10: FOH | D10: 16 | E10: =D10+D11 -> 36 | F10: =E10*G22 -> 756000 | G10: 16 | H10: =G10+G11 -> 36 | I10: =H10*G22 -> 756000 | J10: 16 | K10: =J10+J11 -> 36 | L10: =K10*G22 -> 756000 | M10: 20 | N10: =M10+M11 -> 40 | O10: =N10*G22 -> 840000 | P10: 20 | Q10: =P10+P11 -> 45 | R10: =Q10*G22 -> 945000 | S10: 35 | T10: =S10+S11 -> 70 | U10: =T10*G22 -> 1470000 | V10: 35 | W10: =V10+V11 -> 70 | X10: =W10*G22 -> 1470000
C11: BOH | D11: 20 | G11: 20 | J11: 20 | M11: 20 | P11: 25 | S11: 35 | V11: 35
B12: Total | E12: =E5+E6+E9+E10 -> 95 | F12: =F5+F6+F9+F10 -> 2414076.9 | H12: =H5+H6+H9+H10 -> 95 | I12: =I5+I6+I9+I10 -> 2414076.9 | K12: =K5+K6+K9+K10 -> 95 | L12: =L5+L6+L9+L10 -> 2414076.9 | N12: =N5+N6+N9+N10 -> 99 | O12: =O5+O6+O9+O10 -> 2498076.9 | Q12: =Q5+Q6+Q9+Q10 -> 113 | R12: =R5+R6+R9+R10 -> 2931769.2 | T12: =T5+T6+T9+T10 -> 172 | U12: =U5+U6+U9+U10 -> 4170769.2 | W12: =W5+W6+W9+W10 -> 172 | X12: =X5+X6+X9+X10 -> 4170769.2
C14: Lương | E14: Lương trung bình Mngt | F14: Lương Mngt /ngày | G14: Lương/giờ
B15: RGM | C15: 12000000
B16: ARM | C16: 8000000
B17: SL | C17: 6000000
B18: SL | C18: 6000000 | E18: =AVERAGE(C15:C18) -> 8000000 | F18: =E18/26 -> 307692.31 | G18: =F18/8 -> 38461.538
B20: 3* | C20: 22000
B21: 2* | C21: 21000
B22: 1* | C22: 20000 | G22: =AVERAGE(C20:C22) -> 21000
A24: Sale forcasting /Week | C24: =SUM(C26:C32) -> 179000000
B26: Mon | C26: 15000000
B27: Tue | C27: 15000000
B28: Wed | C28: 17000000
B29: Thu | C29: 20000000
B30: Fri | C30: 22000000
B31: Sat | C31: 45000000
B32: Sun | C32: 45000000

Sheet Savico
A3: Week 4 | C3: Day | D3: Mon | G3: Tue | J3: Wed | M3: Thu | P3: Fri | S3: Sat | V3: Sun
C4: ITEM | D4: Hour | E4: Total Hr | F4: Salary/hr | G4: Hour | H4: Total Hr | I4: Salary/hr | J4: Hour | K4: Total Hr | L4: Salary/hr | M4: Hour | N4: Total Hr | O4: Salary/hr | P4: Hour | Q4: Total Hr | R4: Salary/hr | S4: Hour | T4: Total Hr | U4: Salary/hr | V4: Hour | W4: Total Hr | X4: Salary/hr
A5: SAVICO | B5: Morning | C5: Mngt | D5: 8 | E5: =8 -> 8 | F5: =E5*G18 -> 352564.1 | G5: 8 | H5: =8 -> 8 | I5: =H5*G18 -> 352564.1 | J5: 8 | K5: =8 -> 8 | L5: =K5*G18 -> 352564.1 | M5: 8 | N5: =8 -> 8 | O5: =N5*G18 -> 352564.1 | P5: 8 | Q5: =P5 -> 8 | R5: =Q5*G18 -> 352564.1 | S5: 8 | T5: =S5 -> 8 | U5: =T5*G18 -> 352564.1 | V5: 8 | W5: =V5 -> 8 | X5: =W5*G18 -> 352564.1
C6: FOH | D6: 14 | E6: =D6+D7 -> 33 | F6: =E6*G22 -> 693000 | G6: 14 | H6: =G6+G7 -> 33 | I6: =H6*G22 -> 693000 | J6: 14 | K6: =J6+J7 -> 33 | L6: =K6*G22 -> 693000 | M6: 14 | N6: =M6+M7 -> 33 | O6: =N6*G22 -> 693000 | P6: 14 | Q6: =P6+P7 -> 33 | R6: =Q6*G22 -> 693000 | S6: 30 | T6: =S6+S7 -> 65 | U6: =T6*G22 -> 1365000 | V6: 30 | W6: =V6+V7 -> 65 | X6: =W6*G22 -> 1365000
C7: BOH | D7: 19 | G7: 19 | J7: 19 | M7: 19 | P7: 19 | S7: 35 | V7: 35
B9: Afternoon | C9: Mngt | D9: 8 | E9: =D9 -> 8 | F9: =E9*G18 -> 352564.1 | G9: 8 | H9: =G9 -> 8 | I9: =H9*G18 -> 352564.1 | J9: 8 | K9: =J9 -> 8 | L9: =K9*G18 -> 352564.1 | M9: 8 | N9: =M9 -> 8 | O9: =N9*G18 -> 352564.1 | P9: 16 | Q9: =P9 -> 16 | R9: =Q9*G18 -> 705128.21 | S9: 16 | T9: =S9 -> 16 | U9: =T9*G18 -> 705128.21 | V9: 16 | W9: =V9 -> 16 | X9: =W9*G18 -> 705128.21
C10: FOH | D10: 15 | E10: =D10+D11 -> 34 | F10: =E10*G22 -> 714000 | G10: 16 | H10: =G10+G11 -> 35 | I10: =H10*G22 -> 735000 | J10: 16 | K10: =J10+J11 -> 35 | L10: =K10*G22 -> 735000 | M10: 16 | N10: =M10+M11 -> 35 | O10: =N10*G22 -> 735000 | P10: 20 | Q10: =P10+P11 -> 41 | R10: =Q10*G22 -> 861000 | S10: 30 | T10: =S10+S11 -> 65 | U10: =T10*G22 -> 1365000 | V10: 30 | W10: =V10+V11 -> 65 | X10: =W10*G22 -> 1365000
C11: BOH | D11: 19 | G11: 19 | J11: 19 | M11: 19 | P11: 21 | S11: 35 | V11: 35
B12: Total | E12: =E5+E6+E9+E10 -> 83 | F12: =F5+F6+F9+F10 -> 2112128.2 | H12: =H5+H6+H9+H10 -> 84 | I12: =I5+I6+I9+I10 -> 2133128.2 | K12: =K5+K6+K9+K10 -> 84 | L12: =L5+L6+L9+L10 -> 2133128.2 | N12: =N5+N6+N9+N10 -> 84 | O12: =O5+O6+O9+O10 -> 2133128.2 | Q12: =Q5+Q6+Q9+Q10 -> 98 | R12: =R5+R6+R9+R10 -> 2611692.3 | T12: =T5+T6+T9+T10 -> 154 | U12: =U5+U6+U9+U10 -> 3787692.3 | W12: =W5+W6+W9+W10 -> 154 | X12: =X5+X6+X9+X10 -> 3787692.3
C14: Lương | E14: Lương trung bình Mngt | F14: Lương Mngt /ngày | G14: Lương/giờ
B15: RGM | C15: 13500000
B16: ARM | C16: 8000000
B17: SL | C17: 6000000
E18: =AVERAGE(C15:C18) -> 9166666.7 | F18: =E18/26 -> 352564.1 | G18: =F18/8 -> 44070.513
B20: 3* | C20: 22000
B21: 2* | C21: 21000
B22: 1* | C22: 20000 | G22: =AVERAGE(C20:C22) -> 21000
A24: Sale forcasting /Week | C24: =SUM(C26:C32) -> 146000000
B26: Mon | C26: 12000000
B27: Tue | C27: 12000000
B28: Wed | C28: 12000000
B29: Thu | C29: 13000000
B30: Fri | C30: 17000000
B31: Sat | C31: 40000000
B32: Sun | C32: 40000000

Sheet Pico
A3: Week 4 | C3: Day | D3: Mon | G3: Tue | J3: Wed | M3: Thu | P3: Fri | S3: Sat | V3: Sun
C4: ITEM | D4: Hour | E4: Total Hr | F4: Salary/hr | G4: Hour | H4: Total Hr | I4: Salary/hr | J4: Hour | K4: Total Hr | L4: Salary/hr | M4: Hour | N4: Total Hr | O4: Salary/hr | P4: Hour | Q4: Total Hr | R4: Salary/hr | S4: Hour | T4: Total Hr | U4: Salary/hr | V4: Hour | W4: Total Hr | X4: Salary/hr
A5: PICO | B5: Morning | C5: Mngt | D5: 8 | E5: =8 -> 8 | F5: =E5*G17 -> 307692.31 | G5: 8 | H5: =8 -> 8 | I5: =H5*G17 -> 307692.31 | J5: 8 | K5: =8 -> 8 | L5: =K5*G17 -> 307692.31 | M5: 8 | N5: =8 -> 8 | O5: =N5*G17 -> 307692.31 | P5: 8 | Q5: =P5 -> 8 | R5: =Q5*G17 -> 307692.31 | S5: 8 | T5: =S5 -> 8 | U5: =T5*G17 -> 307692.31 | V5: 8 | W5: =V5 -> 8 | X5: =W5*G17 -> 307692.31
C6: FOH | D6: 15 | E6: =D6+D7 -> 34 | F6: =E6*G21 -> 714000 | G6: 15 | H6: =G6+G7 -> 34 | I6: =H6*G21 -> 714000 | J6: 15 | K6: =J6+J7 -> 34 | L6: =K6*G21 -> 714000 | M6: 15 | N6: =M6+M7 -> 34 | O6: =N6*G21 -> 714000 | P6: 19 | Q6: =P6+P7 -> 39 | R6: =Q6*G21 -> 819000 | S6: 35 | T6: =S6+S7 -> 70 | U6: =T6*G21 -> 1470000 | V6: 35 | W6: =V6+V7 -> 70 | X6: =W6*G21 -> 1470000
C7: BOH | D7: 19 | G7: 19 | J7: 19 | M7: 19 | P7: 20 | S7: 35 | V7: 35
B9: Afternoon | C9: Mngt | D9: 8 | E9: =D9 -> 8 | F9: =E9*G17 -> 307692.31 | G9: 8 | H9: =G9 -> 8 | I9: =H9*G17 -> 307692.31 | J9: 16 | K9: =J9 -> 16 | L9: =K9*G17 -> 615384.62 | M9: 8 | N9: =M9 -> 8 | O9: =N9*G17 -> 307692.31 | P9: 8 | Q9: =P9 -> 8 | R9: =Q9*G17 -> 307692.31 | S9: 16 | T9: =S9 -> 16 | U9: =T9*G17 -> 615384.62 | V9: 16 | W9: =V9 -> 16 | X9: =W9*G17 -> 615384.62
C10: FOH | D10: 19 | E10: =D10+D11 -> 39 | F10: =E10*G21 -> 819000 | G10: 19 | H10: =G10+G11 -> 39 | I10: =H10*G21 -> 819000 | J10: 19 | K10: =J10+J11 -> 39 | L10: =K10*G21 -> 819000 | M10: 19 | N10: =M10+M11 -> 39 | O10: =N10*G21 -> 819000 | P10: 19 | Q10: =P10+P11 -> 44 | R10: =Q10*G21 -> 924000 | S10: 35 | T10: =S10+S11 -> 70 | U10: =T10*G21 -> 1470000 | V10: 35 | W10: =V10+V11 -> 70 | X10: =W10*G21 -> 1470000
C11: BOH | D11: 20 | G11: 20 | J11: 20 | M11: 20 | P11: 25 | S11: 35 | V11: 35
B12: Total | E12: =E5+E6+E9+E10 -> 89 | F12: =F5+F6+F9+F10 -> 2148384.6 | H12: =H5+H6+H9+H10 -> 89 | I12: =I5+I6+I9+I10 -> 2148384.6 | K12: =K5+K6+K9+K10 -> 97 | L12: =L5+L6+L9+L10 -> 2456076.9 | N12: =N5+N6+N9+N10 -> 89 | O12: =O5+O6+O9+O10 -> 2148384.6 | Q12: =Q5+Q6+Q9+Q10 -> 99 | R12: =R5+R6+R9+R10 -> 2358384.6 | T12: =T5+T6+T9+T10 -> 164 | U12: =U5+U6+U9+U10 -> 3863076.9 | W12: =W5+W6+W9+W10 -> 164 | X12: =X5+X6+X9+X10 -> 3863076.9
C14: Lương | E14: Lương trung bình Mngt | F14: Lương Mngt /ngày | G14: Lương/giờ
B15: RGM | C15: 12000000
B16: SL | C16: 6000000
B17: SL | C17: 6000000 | E17: =AVERAGE(C15:C17) -> 8000000 | F17: =E17/26 -> 307692.31 | G17: =F17/8 -> 38461.538
B19: 3* | C19: 22000
B20: 2* | C20: 21000
B21: 1* | C21: 20000 | G21: =AVERAGE(C19:C21) -> 21000
A23: Sale forcasting /Week | C23: =SUM(C25:C31) -> 159000000
B25: Mon | C25: 14000000
B26: Tue | C26: 15000000
B27: Wed | C27: 17000000
B28: Thu | C28: 15000000
B29: Fri | C29: 18000000
B30: Sat | C30: 40000000
B31: Sun | C31: 40000000

Sheet Routine task
A1: Position / Responsibilities | B1: tasks | C1: frequency | D1: TIME | E1: RGM | F1: MODs | G1: BOH TMs | H1: CSR | I1: FOH TMs | J1: Rider | K1: start_time | L1: time_out | M1: duration | N1: end_time | O1: 0.25 | P1: =O1+1/48 -> 0.27083333 | Q1: =P1+1/48 -> 0.29166667 | R1: =Q1+1/48 -> 0.3125 | S1: =R1+1/48 -> 0.33333333 | T1: =S1+1/48 -> 0.35416667 | U1: =T1+1/48 -> 0.375 | V1: =U1+1/48 -> 0.39583333 | W1: =V1+1/48 -> 0.41666667 | ... AY1: =AX1+1/48 -> 1 | BB1: Total Minutes | BC1: Total Hours | BD1: Total Minutes | BE1: Total Minutes | BF1: Total Minutes | BG1: Total Minutes | BH1: Total Minutes | BI1: Total Minutes | BJ1: Total Minutes | BK1: Total Minutes | BL1: Total Minutes | BM1: Total Minutes | BN1: Total Minutes | BO1: Total Minutes | BP1: Total Minutes | BQ1: Total Minutes | BR1: Total Minutes | BS1: Total Minutes | BT1: Total Minutes | BU1: Total Minutes | BV1: Total Minutes | BW1: Total Minutes | BX1: Total Minutes | BY1: Total Minutes | BZ1: Total Minutes | CA1: Total Minutes | CB1: Total Minutes | CC1: Total Minutes | CD1: Total Minutes | CE1: Total Minutes | CF1: Total Minutes | CG1: Total Minutes | CH1: Total Minutes | CI1: Total Minutes | CJ1: Total Minutes | CK1: Total Minutes | CL1: Total Minutes | CM1: Total Minutes | CN1: Total Minutes | CO1: Total Minutes | CP1: Total Minutes | CQ1: Total Minutes | CR1: Total Minutes | CS1: Total Minutes | CT1: Total Minutes | CU1: Total Minutes | CV1: Total Minutes | CW1: Total Minutes | CX1: Total Minutes | CY1: Total Minutes | CZ1: Total Minutes | DA1: Total Minutes | DB1: Total Minutes | DC1: Total Minutes | DD1: Total Minutes | DE1: Total Minutes | DF1: Total Minutes | DG1: Total Minutes | DH1: Total Minutes | DI1: Total Minutes | DJ1: Total Minutes | DK1: Total Minutes | DL1: Total Minutes | DM1: Total Minutes | DN1: Total Minutes | DO1: Total Minutes | DP1: Total Minutes | DQ1: Total Minutes | DR1: Total Minutes | DS1: Total Minutes | DT1: Total Minutes | DU1: Total Minutes | DV1: Total Minutes | DW1: Total Minutes | DX1: Total Minutes | DY1: Total Minutes | DZ1: Total Minutes | EA1: Total Minutes | EB1: Total Minutes | EC1: Total Minutes | ED1: Total Minutes | EE1: Total Minutes | EF1: Total Minutes | EG1: Total Minutes | EH1: Total Minutes | EI1: Total Minutes | EJ1: Total Minutes | EK1: Total Minutes | EL1: Total Minutes | EM1: Total Minutes | EN1: Total Minutes | EO1: Total Minutes | EP1: Total Minutes | EQ1: Total Minutes | ER1: Total Minutes | ES1: Total Minutes | ET1: Total Minutes | EU1: Total Minutes | EV1: Total Minutes | EW1: Total Minutes | EX1: Total Minutes | EY1: Total Minutes | EZ1: Total Minutes | FA1: Total Minutes | FB1: Total Minutes | FC1: Total Minutes | FD1: Total Minutes | FE1: Total Minutes | FF1: Total Minutes | FG1: Total Minutes | FH1: Total Minutes | FI1: Total Minutes | FJ1: Total Minutes | FK1: Total Minutes | FL1: Total Minutes | FM1: Total Minutes | FN1: Total Minutes | FO1: Total Minutes | FP1: Total Minutes | FQ1: Total Minutes | FR1: Total Minutes | FS1: Total Minutes | FT1: Total Minutes | FU1: Total Minutes | FV1: Total Minutes | FW1: Total Minutes | FX1: Total Minutes | FY1: Total Minutes | FZ1: Total Minutes | GA1: Total Minutes | GB1: Total Minutes | GC1: Total Minutes | GD1: Total Minutes | GE1: Total Minutes | GF1: Total Minutes | GG1: Total Minutes | GH1: Total Minutes | GI1: Total Minutes | GJ1: Total Minutes | GK1: Total Minutes | GL1: Total Minutes | GM1: Total Minutes | GN1: Total Minutes | GO1: Total Minutes | GP1: Total Minutes | GQ1: Total Minutes | GR1: Total Minutes | GS1: Total Minutes | GT1: Total Minutes | GU1: Total Minutes | GV1: Total Minutes | GW1: Total Minutes | GX1: Total Minutes | GY1: Total Minutes | GZ1: Total Minutes | HA1: Total Minutes | HB1: Total Minutes | HC1: Total Minutes | HD1: Total Minutes | HE1: Total Minutes | HF1: Total Minutes | HG1: Total Minutes | HH1: Total Minutes | HI1: Total Minutes | HJ1: Total Minutes | HK1: Total Minutes | HL1: Total Minutes | HM1: Total Minutes | HN1: Total Minutes | HO1: Total Minutes | HP1: Total Minutes | HQ1: Total Minutes | HR1: Total Minutes | HS1: Total Minutes | HT1: Total Minutes | HU1: Total Minutes | HV1: Total Minutes | HW1: Total Minutes | HX1: Total Minutes | HY1: Total Minutes | HZ1: Total Minutes | IA1: Total Minutes | IB1: Total Minutes | IC1: Total Minutes | ID1: Total Minutes | IE1: Total Minutes | IF1: Total Minutes | IG1: Total Minutes | IH1: Total Minutes
A2: MOD | B2: RGS / OPENING SHIFT / CHECK-IN | C2: Daily | D2: Fixed | F2: 1 | J2: 1 | K2: 0.33333333 | L2: 0 | M2: =BB2 -> 5 | N2: 0.33680556 | S2: 5 | BB2: =SUM(O2:BA2) -> 5 | BC2: =BB2/60 -> 0.083333333
A3: BOH | B3: PAN DOUGH MAKING (morning) | C3: Daily | D3: Fixed | F3: 1 | J3: 1 | K3: 0.33333333 | L3: =K3-K2 -> 0 | M3: =BB3 -> 100 | N3: 0.40277778 | S3: 30 | T3: 50 | U3: 10 | V3: 5 | W3: 5 | BB3: =SUM(O3:BA3) -> 100 | BC3: =BB3/60 -> 1.6666667
A4: BOH | B4: OPENING CLEANING BOH | C4: Daily | D4: Fixed | F4: 1 | G4: 1 | J4: 1 | K4: 0.33680556 | L4: =(K4-K3)*48*30 -> 5 | M4: =BB4 -> 15 | N4: 0.34722222 | S4: 15 | BB4: =SUM(O4:BA4) -> 15 | BC4: =BB4/60 -> 0.25
A5: MOD | B5: ADMIN WORKS (morning) | C5: Daily | D5: Fixed | F5: 1 | K5: 0.34722222 | L5: =(K5-K4)*48*30 -> 15 | M5: =BB5 -> 10 | N5: 0.35416667 | S5: 10 | BB5: =SUM(O5:BA5) -> 10 | BC5: =BB5/60 -> 0.16666667
A6: MGNT | B6: Receive Vegieterian | C6: 3/week | D6: Flexible | E6: 1 | F6: 1 | G6: 1 | K6: 0.35416667 | L6: =(K6-K5)*48*30 -> 10 | M6: =BB6 -> 10 | N6: 0.36111111 | T6: 10 | BB6: =SUM(O6:BA6) -> 10 | BC6: =BB6/60 -> 0.16666667
A7: MOD | B7: Banking | C7: Daily | D7: Flexible | F7: 1 | H7: 1 | K7: 0.375 | L7: =(K7-K6)*48*30 -> 30 | M7: =BB7 -> 30 | N7: 0.39583333 | U7: 30 | BB7: =SUM(O7:BA7) -> 30 | BC7: =BB7/60 -> 0.5
A8: MOD | B8: Check Chiller/freezer/ FS Checklist (morning) | C8: Daily | D8: Flexible | F8: 1 | G8: 1 | K8: 0.375 | L8: =(K8-K7)*48*30 -> 0 | M8: =BB8 -> 10 | N8: 0.38194444 | U8: 10 | BB8: =SUM(O8:BA8) -> 10 | BC8: =BB8/60 -> 0.16666667
A9: FOH | B9: Cleaning glasses / Signage | C9: Daily | D9: Fixed | G9: 1 | H9: 1 | K9: 0.375 | L9: =(K9-K8)*48*30 -> 0 | M9: =BB9 -> 10 | N9: 0.38194444 | U9: 10 | BB9: =SUM(O9:BA9) -> 10 | BC9: =BB9/60 -> 0.16666667
A10: BOH | B10: MAKE /AUX TABLE SET-UP (morning) | D10: Fixed | F10: 1 | G10: 1 | K10: 0.37847222 | L10: =(K10-K9)*48*30 -> 5 | M10: =BB10 -> 50 | N10: 0.41319444 | U10: 25 | V10: 25 | BB10: =SUM(O10:BA10) -> 50 | BC10: =BB10/60 -> 0.83333333
A11: BOH | B11: CUT/BAR TABLE SET-UP (morning) | D11: Fixed | F11: 1 | J11: 1 | K11: 0.38541667 | L11: =(K11-K10)*48*30 -> 10 | M11: =BB11 -> 30 | N11: 0.40625 | U11: 15 | V11: 15 | BB11: =SUM(O11:BA11) -> 30 | BC11: =BB11/60 -> 0.5
A12: BOH | B12: Cutting of ingredients (morning) | C12: Daily | D12: Flexible | F12: 1 | G12: 1 | J12: 1 | K12: 0.38541667 | L12: =(K12-K11)*48*30 -> 0 | M12: =BB12 -> 35 | N12: 0.40972222 | U12: 15 | V12: 10 | X12: 10 | BB12: =SUM(O12:BA12) -> 35 | BC12: =BB12/60 -> 0.58333333
A13: ALL | B13: Rest room Clearning (morning) | C13: Daily | D13: Flexible | K13: 0.38888889 | L13: =(K13-K12)*48*30 -> 5 | M13: =BB13 -> 10 | N13: 0.39583333 | V13: 10 | BB13: =SUM(O13:BA13) -> 10 | BC13: =BB13/60 -> 0.16666667
A14: ALL | B14: DELIVERY MOTOR BIKES CHECKING | C14: Daily | D14: Flexible | F14: 1 | J14: 1 | K14: 0.39583333 | L14: =(K14-K13)*48*30 -> 10 | M14: =BB14 -> 20 | N14: 0.40972222 | V14: 15 | W14: 5 | BB14: =SUM(O14:BA14) -> 20 | BC14: =BB14/60 -> 0.33333333
A15: MOD | B15: Approved working hours on Cadena | C15: Daily | D15: Flexible | F15: 1 | K15: 0.39583333 | L15: =(K15-K14)*48*30 -> 0 | M15: =BB15 -> 5 | N15: 0.39930556 | V15: 5 | BB15: =SUM(O15:BA15) -> 5 | BC15: =BB15/60 -> 0.083333333
A16: MOD | B16: Follow up MRD Labels (morning) | C16: Daily | D16: Flexible | F16: 1 | G16: 1 | K16: 0.39583333 | L16: =(K16-K15)*48*30 -> 0 | M16: =BB16 -> 10 | N16: 0.38194444 | V16: 10 | BB16: =SUM(O16:BA16) -> 10 | BC16: =BB16/60 -> 0.16666667
A17: FOH | B17: Sweep / Mop Floor (morning) | C17: Daily | D17: Flexible | G17: 1 | H17: 1 | K17: 0.39583333 | L17: =(K17-K16)*48*30 -> 0 | M17: =BB17 -> 15 | N17: 0.40625 | U17: 15 | BB17: =SUM(O17:BA17) -> 15 | BC17: =BB17/60 -> 0.25
A18: FOH | B18: Cashier check cashflow before opening | C18: Daily | D18: Fixed | F18: 1 | H18: 1 | K18: 0.39583333 | L18: =(K18-K17)*48*30 -> 0 | M18: =BB18 -> 5 | N18: 0.39930556 | V18: 5 | BB18: =SUM(O18:BA18) -> 5 | BC18: =BB18/60 -> 0.083333333
A19: FOH | B19: Set-up table & Prepare dine-in condiments | C19: Daily | D19: Fixed | H19: 1 | K19: 0.40972222 | L19: =(K19-K18)*48*30 -> 20 | M19: =BB19 -> 20 | N19: 0.42361111 | V19: 10 | W19: 10 | BB19: =SUM(O19:BA19) -> 20 | BC19: =BB19/60 -> 0.33333333
A20: BOH | B20: R4R (Make. Aux, Bar) (morning) | C20: Daily | D20: Flexible | G20: 1 | K20: 0.41666667 | L20: =(K20-K19)*48*30 -> 10 | M20: =BB20 -> 40 | N20: 0.44444444 | W20: 30 | X20: 10 | BB20: =SUM(O20:BA20) -> 40 | BC20: =BB20/60 -> 0.66666667
A21: MGNT | B21: Breifing (morning) | C21: Daily | D21: Flexible | E21: 1 | F21: 1 | G21: 1 | H21: 1 | I21: 1 | J21: 1 | K21: 0.41666667 | L21: =(K21-K20)*48*30 -> 0 | M21: =BB21 -> 20 | N21: 0.43055556 | W21: 20 | BB21: =SUM(O21:BA21) -> 20 | BC21: =BB21/60 -> 0.33333333
A22: FOH | B22: Prepare Delievery & Take aways condiments | C22: Daily | D22: Fixed | H22: 1 | K22: 0.43402778 | L22: =(K22-K21)*48*30 -> 25 | M22: =BB22 -> 15 | N22: 0.44444444 | W22: 5 | X22: 10 | BB22: =SUM(O22:BA22) -> 15 | BC22: =BB22/60 -> 0.25
A23: ALL | B23: Fold Pizza Boxes | C23: Daily | D23: Flexible | E23: 1 | F23: 1 | G23: 1 | H23: 1 | I23: 1 | J23: 1 | K23: 0.4375 | L23: =(K23-K22)*48*30 -> 5 | M23: =BB23 -> 10 | N23: 0.44444444 | X23: 10 | BB23: =SUM(O23:BA23) -> 10 | BC23: =BB23/60 -> 0.16666667
A24: BOH | B24: Dish washing (morning) | C24: Daily | D24: Flexible | F24: 1 | G24: 1 | H24: 1 | I24: 1 | J24: 1 | K24: 0.55555556 | L24: =(K24-K23)*48*30 -> 170 | M24: =BB24 -> 60 | N24: 0.59722222 | AC24: 10 | AD24: 30 | AE24: 20 | BB24: =SUM(O24:BA24) -> 60 | BC24: =BB24/60 -> 1
A25: FOH | B25: Dry up culteries, cups and plates (afternoon) | C25: Daily | D25: Flexible | G25: 1 | H25: 1 | I25: 1 | J25: 1 | K25: 0.55555556 | L25: =(K25-K24)*48*30 -> 0 | M25: =BB25 -> 15 | N25: 0.56597222 | AC25: 10 | AD25: 5 | BB25: =SUM(O25:BA25) -> 15 | BC25: =BB25/60 -> 0.25
A26: FOH | B26: Fill culteries, cups and plates (afternoon) | C26: Daily | D26: Flexible | G26: 1 | H26: 1 | I26: 1 | J26: 1 | K26: 0.56597222 | L26: =(K26-K25)*48*30 -> 15 | M26: =BB26 -> 10 | N26: 0.57986111 | AE26: 10 | BB26: =SUM(O26:BA26) -> 10 | BC26: =BB26/60 -> 0.16666667
A27: ALL | B27: Rest room Clearning (after lunch) | C27: Daily | D27: Flexible | K27: 0.58333333 | L27: =(K27-K26)*48*30 -> 25 | M27: =BB27 -> 10 | N27: 0.59027778 | AF27: 10 | BB27: =SUM(O27:BA27) -> 10 | BC27: =BB27/60 -> 0.16666667
A28: BOH | B28: Cutting of ingredients (afternoon) | C28: Daily | D28: Flexible | F28: 1 | G28: 1 | J28: 1 | K28: 0.60416667 | L28: =(K28-K27)*48*30 -> 30 | M28: =BB28 -> 70 | N28: 0.65277778 | AF28: 30 | AG28: 10 | AI28: 10 | AJ28: 20 | BB28: =SUM(O28:BA28) -> 70 | BC28: =BB28/60 -> 1.1666667
A29: FOH | B29: Sweep / Mop Floor (afternoon) | C29: Daily | D29: Flexible | G29: 1 | H29: 1 | K29: 0.60416667 | L29: =(K29-K28)*48*30 -> 0 | M29: =BB29 -> 15 | N29: 0.61458333 | AF29: 15 | BB29: =SUM(O29:BA29) -> 15 | BC29: =BB29/60 -> 0.25
A30: FOH | B30: Prepare Delievery & Take aways condiments | C30: Daily | D30: Fixed | H30: 1 | K30: 0.61805556 | L30: =(K30-K29)*48*30 -> 20 | M30: =BB30 -> 25 | N30: 0.64583333 | AF30: 10 | AG30: 15 | BB30: =SUM(O30:BA30) -> 25 | BC30: =BB30/60 -> 0.41666667
A31: BOH | B31: Make Soup and Sauces | C31: Daily | D31: Flexible | F31: 1 | G31: 1 | K31: 0.625 | L31: =(K31-K30)*48*30 -> 10 | M31: =BB31 -> 30 | N31: 0.64583333 | AG31: 30 | BB31: =SUM(O31:BA31) -> 30 | BC31: =BB31/60 -> 0.5
A32: BOH | B32: Prepare Appertizer | C32: Daily | D32: Flexible | F32: 1 | G32: 1 | K32: 0.625 | L32: =(K32-K31)*48*30 -> 0 | M32: =BB32 -> 10 | N32: 0.63194444 | AG32: 10 | BB32: =SUM(O32:BA32) -> 10 | BC32: =BB32/60 -> 0.16666667
A33: BOH | B33: Frozen foods Defrosting | C33: Daily | D33: Flexible | F33: 1 | K33: 0.625 | L33: =(K33-K32)*48*30 -> 0 | M33: =BB33 -> 5 | N33: 0.62847222 | AG33: 5 | BB33: =SUM(O33:BA33) -> 5 | BC33: =BB33/60 -> 0.083333333
A34: MOD | B34: ADMIN WORKS (afternoon) | C34: Daily | D34: Fixed | F34: 1 | K34: 0.64583333 | L34: =(K34-K33)*48*30 -> 30 | M34: =BB34 -> 15 | N34: 0.35416667 | AH34: 15 | BB34: =SUM(O34:BA34) -> 15 | BC34: =BB34/60 -> 0.25
A35: BOH | B35: PAND DOUGH MAKING (afternoon) | C35: Daily | D35: Fixed | F35: 1 | J35: 1 | K35: 0.64583333 | L35: =(K35-K34)*48*30 -> 0 | M35: =BB35 -> 50 | N35: 0.68055556 | AH35: 50 | BB35: =SUM(O35:BA35) -> 50 | BC35: =BB35/60 -> 0.83333333
A36: MGNT | B36: Order Vegieterian | C36: 3/week | D36: Flexible | E36: 1 | F36: 1 | K36: 0.64583333 | L36: =(K36-K35)*48*30 -> 0 | M36: =BB36 -> 5 | N36: 0.64930556 | AH36: 5 | BB36: =SUM(O36:BA36) -> 5 | BC36: =BB36/60 -> 0.083333333
A37: BOH | B37: Prepare Spaghetti & Rice | C37: Daily | D37: Flexible | F37: 1 | G37: 1 | K37: 0.66666667 | L37: =(K37-K36)*48*30 -> 30 | M37: =BB37 -> 20 | N37: 0.68055556 | AI37: 20 | BB37: =SUM(O37:BA37) -> 20 | BC37: =BB37/60 -> 0.33333333
A38: BOH | B38: Prepare HT Dough | C38: 2-3/Week | D38: Flexible | G38: 1 | K38: 0.66666667 | L38: =(K38-K37)*48*30 -> 0 | M38: =BB38 -> 30 | N38: 0.6875 | AI38: 30 | BB38: =SUM(O38:BA38) -> 30 | BC38: =BB38/60 -> 0.5
A39: MOD | B39: Check Chiller/freezer/ FS Checklist (afternoon) | C39: Daily | D39: Flexible | F39: 1 | G39: 1 | K39: 0.66666667 | L39: =(K39-K38)*48*30 -> 0 | M39: =BB39 -> 5 | N39: 0.67013889 | AI39: 5 | BB39: =SUM(O39:BA39) -> 5 | BC39: =BB39/60 -> 0.083333333
A40: MOD | B40: Follow up MRD Labels (afternoon) | C40: Daily | D40: Flexible | F40: 1 | G40: 1 | K40: 0.66666667 | L40: =(K40-K39)*48*30 -> 0 | M40: =BB40 -> 5 | N40: 0.67013889 | AI40: 5 | BB40: =SUM(O40:BA40) -> 5 | BC40: =BB40/60 -> 0.083333333
...

Sheet Daily task
A1: Type the title of this Excel model into this cell | J1: Sales mixed | L1: Trans. | M1: =SUM(M2:M4) -> 41 | N1: =I2/(SUM(M2:M4)) -> 243902.44
A2: Sheet "Activities input" | H2: Sales Forecast (maximize) | I2: 10000000 | J2: DI | K2: 0.3 | L2: =$I$2*K2 -> 3000000 | M2: =L2/N2 -> 15 | N2: 200000
A3: Update 100421 | H3: Baline working hours (minimize) | I3: =BQ66 -> 70.25 | J3: TA | K3: 0.4 | L3: =$I$2*K3 -> 4000000 | M3: =L3/N3 -> 16 | N3: 250000
H4: Productivity | I4: =I2/I3 -> 142348.75 | J4: DE | K4: 0.3 | L4: =$I$2*K4 -> 3000000 | M4: =L4/N4 -> 10 | N4: 300000 | Y4: 1 | Z4: 2 | AA4: 3 | AB4: 4
B5: Task List | I5: Human Resources Requirements | O5: PT/FT Responsibility | Q5: Driving Factor | R5: Frequency by Day | Y5: Frequency by Week | AC5: Time Slot（mins required for every time slot）
B6: Position / Responsibilities | C6: TASKS | D6: Training Requirement | E6: Frequency | F6: TIME | G6: THỜI GIAN | H6: GHI CHÚ | I6: RGM | J6: MODs | K6: BOH TMs | L6: CSR | M6: FOH TMs | N6: Dough/Rider | O6: FT | P6: PT | Q6: Driving of the required time | R6: Mondy | S6: Tuesday | T6: Wednesday | U6: Thursday | V6: Friday | W6: Saturday | X6: Sunday | Y6: Week 1 | Z6: Week 2 | AA6: Week 3 | AB6: Week 4 | AC6: 0.25 | AD6: =AC6+1/48 -> 0.27083333 | AE6: =AD6+1/48 -> 0.29166667 | AF6: =AE6+1/48 -> 0.3125 | AG6: =AF6+1/48 -> 0.33333333 | AH6: =AG6+1/48 -> 0.35416667 | AI6: =AH6+1/48 -> 0.375 | AJ6: =AI6+1/48 -> 0.39583333 | AK6: =AJ6+1/48 -> 0.41666667 | ... BM6: =BL6+1/48 -> 1 | BP6: Total Minutes | BQ6: Total Hours | BR6: Total Minutes | BS6: Total Minutes | BT6: Total Minutes | BU6: Total Minutes | BV6: Total Minutes | BW6: Total Minutes | BX6: Total Minutes | BY6: Total Minutes | BZ6: Total Minutes | CA6: Total Minutes | CB6: Total Minutes | CC6: Total Minutes | CD6: Total Minutes | CE6: Total Minutes | CF6: Total Minutes | CG6: Total Minutes | CH6: Total Minutes | CI6: Total Minutes | CJ6: Total Minutes | CK6: Total Minutes | CL6: Total Minutes | CM6: Total Minutes | CN6: Total Minutes | CO6: Total Minutes | CP6: Total Minutes | CQ6: Total Minutes | CR6: Total Minutes | CS6: Total Minutes | CT6: Total Minutes | CU6: Total Minutes | CV6: Total Minutes | CW6: Total Minutes | CX6: Total Minutes | CY6: Total Minutes | CZ6: Total Minutes | DA6: Total Minutes | DB6: Total Minutes | DC6: Total Minutes | DD6: Total Minutes | DE6: Total Minutes | DF6: Total Minutes | DG6: Total Minutes | DH6: Total Minutes | DI6: Total Minutes | DJ6: Total Minutes | DK6: Total Minutes | DL6: Total Minutes | DM6: Total Minutes | DN6: Total Minutes | DO6: Total Minutes | DP6: Total Minutes | DQ6: Total Minutes | DR6: Total Minutes | DS6: Total Minutes | DT6: Total Minutes | DU6: Total Minutes | DV6: Total Minutes | DW6: Total Minutes | DX6: Total Minutes | DY6: Total Minutes | DZ6: Total Minutes | EA6: Total Minutes | EB6: Total Minutes | EC6: Total Minutes | ED6: Total Minutes | EE6: Total Minutes | EF6: Total Minutes | EG6: Total Minutes | EH6: Total Minutes | EI6: Total Minutes | EJ6: Total Minutes | EK6: Total Minutes | EL6: Total Minutes | EM6: Total Minutes | EN6: Total Minutes | EO6: Total Minutes | EP6: Total Minutes | EQ6: Total Minutes | ER6: Total Minutes | ES6: Total Minutes | ET6: Total Minutes | EU6: Total Minutes | EV6: Total Minutes | EW6: Total Minutes | EX6: Total Minutes | EY6: Total Minutes | EZ6: Total Minutes | FA6: Total Minutes | FB6: Total Minutes | FC6: Total Minutes | FD6: Total Minutes | FE6: Total Minutes | FF6: Total Minutes | FG6: Total Minutes | FH6: Total Minutes | FI6: Total Minutes | FJ6: Total Minutes | FK6: Total Minutes | FL6: Total Minutes | FM6: Total Minutes | FN6: Total Minutes | FO6: Total Minutes | FP6: Total Minutes | FQ6: Total Minutes | FR6: Total Minutes | FS6: Total Minutes | FT6: Total Minutes | FU6: Total Minutes | FV6: Total Minutes | FW6: Total Minutes | FX6: Total Minutes | FY6: Total Minutes | FZ6: Total Minutes | GA6: Total Minutes | GB6: Total Minutes | GC6: Total Minutes | GD6: Total Minutes | GE6: Total Minutes | GF6: Total Minutes | GG6: Total Minutes | GH6: Total Minutes | GI6: Total Minutes | GJ6: Total Minutes | GK6: Total Minutes | GL6: Total Minutes | GM6: Total Minutes | GN6: Total Minutes | GO6: Total Minutes | GP6: Total Minutes | GQ6: Total Minutes | GR6: Total Minutes | GS6: Total Minutes | GT6: Total Minutes | GU6: Total Minutes | GV6: Total Minutes | GW6: Total Minutes | GX6: Total Minutes | GY6: Total Minutes | GZ6: Total Minutes | HA6: Total Minutes | HB6: Total Minutes | HC6: Total Minutes | HD6: Total Minutes | HE6: Total Minutes | HF6: Total Minutes | HG6: Total Minutes | HH6: Total Minutes | HI6: Total Minutes | HJ6: Total Minutes | HK6: Total Minutes | HL6: Total Minutes | HM6: Total Minutes | HN6: Total Minutes | HO6: Total Minutes | HP6: Total Minutes | HQ6: Total Minutes | HR6: Total Minutes | HS6: Total Minutes | HT6: Total Minutes | HU6: Total Minutes | HV6: Total Minutes | HW6: Total Minutes | HX6: Total Minutes | HY6: Total Minutes | HZ6: Total Minutes | IA6: Total Minutes | IB6: Total Minutes | IC6: Total Minutes | ID6: Total Minutes | IE6: Total Minutes | IF6: Total Minutes | IG6: Total Minutes | IH6: Total Minutes | II6: Total Minutes | IJ6: Total Minutes | IK6: Total Minutes | IL6: Total Minutes | IM6: Total Minutes | IN6: Total Minutes | IO6: Total Minutes | IP6: Total Minutes | IQ6: Total Minutes | IR6: Total Minutes | IS6: Total Minutes | IT6: Total Minutes | IU6: Total Minutes | IV6: Total Minutes
A7: 1 | B7: MOD | C7: RGS / OPENING SHIFT / CHECK-IN | D7: Specific | E7: Daily | F7: Fixed | G7: Morning | H7: Mở cửa cùng 1 nhân viên; thực hiện security & safety check | J7: x | N7: x | O7: x | P7: x | Q7: TC | R7: x | S7: x | T7: x | U7: x | V7: x | W7: x | X7: x | Y7: x | Z7: x | AA7: x | AB7: x | AG7: 5 | BP7: =SUM(AC7:BO7) -> 5 | BQ7: =BP7/60 -> 0.083333333
A8: 2 | B8: MOD | C8: ADMIN WORKS | D8: Specific | E8: Daily | F8: Fixed | G8: Morning | H8: Check mail, đọc logbook, kế hoạch chuẩn bị hàng hóa | J8: x | O8: x | P8: x | Q8: TC | R8: x | S8: x | T8: x | U8: x | V8: x | W8: x | X8: x | Y8: x | Z8: x | AA8: x | AB8: x | AG8: 10 | AV8: 15 | BJ8: 10 | BP8: =SUM(AC8:BO8) -> 35 | BQ8: =BP8/60 -> 0.58333333
A9: 3 | B9: BOH | C9: OPENING CLEANING BOH | D9: Basic | E9: Daily | F9: Fixed | G9: Morning | J9: x | K9: x | N9: x | O9: x | P9: x | Q9: TC | R9: x | S9: x | T9: x | U9: x | V9: x | W9: x | X9: x | Y9: x | Z9: x | AA9: x | AB9: x | AG9: 15 | BP9: =SUM(AC9:BO9) -> 15 | BQ9: =BP9/60 -> 0.25
A10: 4 | B10: BOH | C10: PAN DOUGH MAKING | D10: Specific | E10: Daily | F10: Fixed | G10: Morning/Afternoon | H10: 1. Ca sáng: 08.10 làm Dough với sự hỗ trợ của MOD. 8.10-8.35: 1/2 mẻ Pan; 8.35-9.00: 1/2 mẻ (1/4 Pan & 1/4 SCP); Sau khi hoàn thành, follow-up Dough theo quy trình đồng thời support bộ phận khác. 2. Ca chiều: Linh hoạt thời gian thực tế, làm bổ sung 1/2 mẻ Pan dough. | J10: x | N10: x | O10: x | P10: x | Q10: TC | R10: x | S10: x | T10: x | U10: x | V10: x | W10: x | X10: x | Y10: x | Z10: x | AA10: x | AB10: x | AG10: 30 | AH10: 50 | AI10: 10 | AJ10: 5 | AK10: 5 | AV10: 50 | BP10: =SUM(AC10:BO10) -> 150 | BQ10: =BP10/60 -> 2.5
A11: 5 | B11: BOH | C11: MAKE /AUX / CUT/BAR TABLE SET-UP | F11: Fixed | H11: 80% nguyên liệu đã được chuẩn bị từ ngày hôm trước | J11: x | K11: x | N11: x | AI11: 30 | AJ11: 45 | AY11: 20 | AZ11: 15 | BP11: =SUM(AC11:BO11) -> 110 | BQ11: =BP11/60 -> 1.8333333
A12: 6 | B12: BOH | C12: Cutting of ingredients | D12: Basic | E12: Daily | F12: Flexible | G12: Morning/Afternoon | H12: - Ca sáng cắt thái chuẩn bị 1 số nguyên liệu AC: Hành, ớt qua lò, Bacon qua lò, Đồ rau củ cho cơm trong menu 39k, Cheesy pop, … - Ca chiều cắt thái đồ chuẩn bị cho ngày hôm sau (có thể fix thời gian theo preplan) | J12: x | K12: x | N12: x | O12: x | P12: x | Q12: TC | R12: x | S12: x | T12: x | U12: x | V12: x | W12: x | X12: x | Y12: x | Z12: x | AA12: x | AB12: x | AI12: 15 | AJ12: 10 | AL12: 10 | AT12: 30 | AU12: 10 | AW12: 10 | AX12: 20 | BP12: =SUM(AC12:BO12) -> 105 | BQ12: =BP12/60 -> 1.75
A13: 7 | B13: BOH | C13: Make Soup and Sauces | D13: Basic | E13: Daily | F13: Flexible | G13: Morning/Afternoon | J13: x | K13: x | AU13: 30 | BP13: =SUM(AC13:BO13) -> 30 | BQ13: =BP13/60 -> 0.5
A14: 8 | B14: BOH | C14: Prepare Spaghetti & Rice | D14: Basic | E14: Daily | F14: Flexible | G14: Morning/Afternoon | J14: x | K14: x | AW14: 20 | BP14: =SUM(AC14:BO14) -> 20 | BQ14: =BP14/60 -> 0.33333333
A15: 9 | B15: BOH | C15: Prepare Appertizer | D15: Basic | E15: Daily | F15: Flexible | G15: Morning/Afternoon | J15: x | K15: x | AU15: 10 | BP15: =SUM(AC15:BO15) -> 10 | BQ15: =BP15/60 -> 0.16666667
A16: 10 | B16: BOH | C16: Frozen foods Defrosting | D16: Specific/Basic | E16: Daily | F16: Flexible | J16: x | AU16: 5 | BP16: =SUM(AC16:BO16) -> 5 | BQ16: =BP16/60 -> 0.083333333
A17: 11 | B17: BOH | C17: Prepare T&C Dough | D17: Specific | E17: 2-3/Week | F17: Flexible | G17: Afternoon | H17: Thời gian làm TnC Dough 15'/0.5 batch trong 10' (shelflife 8h); thời gian cán dough vào chảo trong 30' (shelflife 60h); khoảng 2-3 lần/tuần. | K17: x | O17: x | P17: x | Q17: TC | R17: x | S17: x | T17: x | U17: x | V17: x | W17: x | X17: x | Y17: x | Z17: x | AA17: x | AB17: x | AX17: 20 | BP17: =SUM(AC17:BO17) -> 20 | BQ17: =BP17/60 -> 0.33333333
A18: 12 | B18: BOH | C18: Prepare HT Dough | D18: Specific | E18: 2-3/Week | F18: Flexible | G18: Afternoon | H18: Thời gian làm HT Dough 30'/0.5 batch, thời gian thực hiện linh hoạt theo (selflife 40h); khoảng 2-3 lần/tuần. | K18: x | O18: x | P18: x | Q18: TC | R18: x | S18: x | T18: x | U18: x | V18: x | W18: x | X18: x | Y18: x | Z18: x | AA18: x | AB18: x | AW18: 30 | BP18: =SUM(AC18:BO18) -> 30 | BQ18: =BP18/60 -> 0.5
A19: 13 | B19: BOH | C19: R4R (Make. Aux, Bar) | D19: Basic | E19: Daily | F19: Flexible | G19: Morning/Afternoon | H19: Cuộn viền dough (2 CCP, 1 CBR, 1 half&half, 2 viền LTO, Pre Top, Pre sauce, … trước giờ cao điểm | K19: x | O19: x | P19: x | Q19: TC | R19: x | S19: x | T19: x | U19: x | V19: x | W19: x | X19: x | Y19: x | Z19: x | AA19: x | AB19: x | AK19: 30 | AL19: 10 | AY19: 15 | AZ19: 15 | BP19: =SUM(AC19:BO19) -> 70 | BQ19: =BP19/60 -> 1.1666667
A20: 14 | B20: ALL | C20: DELIVERY MOTOR BIKES CHECKING | D20: Specific/Basic | E20: Daily | F20: Flexible | G20: Morning | H20: Kiểm tra xe giao hàng theo check list trước giờ hoạt động | J20: X | N20: X | AJ20: 15 | AK20: 5 | BP20: =SUM(AC20:BO20) -> 20 | BQ20: =BP20/60 -> 0.33333333
A21: 15 | B21: MOD | C21: Banking | D21: Specific | E21: Daily | F21: Flexible | G21: Morning | H21: 1 quản lý và 1 nhân viên CSR đi banking di chuyển ~20p mỗi chiều) => đi trước 10h | J21: x | L21: X | O21: x | P21: x | Q21: TC | R21: x | S21: x | T21: x | U21: x | V21: x | W21: x | X21: x | Y21: x | Z21: x | AA21: x | AB21: x | AI21: 30 | BP21: =SUM(AC21:BO21) -> 30 | BQ21: =BP21/60 -> 0.5
A22: 16 | B22: MOD | C22: Approved working hours on Cadena | D22: Specific | E22: Daily | F22: Flexible | G22: Morning | H22: Hoàn thành trước 10h sáng | J22: x | O22: x | P22: x | Q22: TC | R22: x | S22: x | T22: x | U22: x | V22: x | W22: x | X22: x | Y22: x | Z22: x | AA22: x | AB22: x | AJ22: 5 | BP22: =SUM(AC22:BO22) -> 5 | BQ22: =BP22/60 -> 0.083333333
A23: 17 | B23: MOD | C23: Check Chiller/freezer/ FS Checklist | D23: Specific | E23: Daily | F23: Flexible | G23: Morning/Afternoon | H23: MIC Kiểm tra nhiệt độ các tủ và ghi chép sổ trước 10h sáng | J23: x | K23: x | O23: x | P23: x | Q23: TC | R23: x | S23: x | T23: x | U23: x | V23: x | W23: x | X23: x | Y23: x | Z23: x | AA23: x | AB23: x | AI23: 10 | AW23: 5 | BP23: =SUM(AC23:BO23) -> 15 | BQ23: =BP23/60 -> 0.25
A24: 18 | B24: MOD | C24: Follow up MRD Labels | D24: Specific | E24: Daily | F24: Flexible | G24: Morning | H24: MIC Kiểm tra MRD các sản phẩm trong các tủ trước 10h sáng | J24: x | K24: x | O24: x | P24: x | Q24: Fixed | R24: x | S24: x | T24: x | U24: x | V24: x | W24: x | X24: x | Y24: x | Z24: x | AA24: x | AB24: x | AJ24: 10 | AW24: 5 | BP24: =SUM(AC24:BO24) -> 15 | BQ24: =BP24/60 -> 0.25
A25: 19 | B25: BOH | C25: Make Station | D25: Specific | E25: Daily | G25: Morning/Afternoon | H25: Trong giờ cao điểm cầ 1 nhân viên đứng độc lập 1 mình, giờ thấp điểm in-charge khu vực BOH. | K25: x | O25: x | P25: x | Q25: TC | R25: x | S25: x | T25: x | U25: x | V25: x | W25: x | X25: x | Y25: x | Z25: x | AA25: x | AB25: x | AK25: 10 | AL25: 10 | AM25: 15 | AN25: 30 | AO25: 30 | AP25: 30 | AQ25: 20 | AR25: 10 | AS25: 10 | AT25: 10 | AU25: 10 | AV25: 10 | AW25: 15 | AX25: 15 | AY25: 15 | AZ25: 30 | BA25: 30 | BB25: 30 | BC25: 30 | BD25: 30 | BE25: 30 | BF25: 20 | BG25: 10 | BH25: 10 | BP25: =SUM(AC25:BO25) -> 460 | BQ25: =BP25/60 -> 7.6666667
A26: 20 | B26: BOH | C26: Aux Station | D26: Specific | E26: Daily | G26: Morning/Afternoon | H26: Kết hợp nhân viên quầy Aux | K26: x | O26: x | P26: x | Q26: TC | R26: x | S26: x | T26: x | U26: x | V26: x | W26: x | X26: x | Y26: x | Z26: x | AA26: x | AB26: x | AK26: 5 | AL26: 10 | AM26: 15 | AN26: 15 | AO26: 15 | AP26: 15 | AQ26: 10 | AR26: 10 | AS26: 10 | AY26: 5 | AZ26: 15 | BA26: 30 | BB26: 30 | BC26: 30 | BD26: 30 | BE26: 30 | BF26: 20 | BG26: 10 | BH26: 5 | BP26: =SUM(AC26:BO26) -> 310 | BQ26: =BP26/60 -> 5.1666667
A27: 21 | B27: BOH | C27: Cut Station | D27: Specific | E27: Daily | G27: Morning/Afternoon | H27: Các quầy chia sẻ công việc của vị trí này | K27: x | O27: x | P27: x | Q27: TC | R27: x | S27: x | T27: x | U27: x | V27: x | W27: x | X27: x | Y27: x | Z27: x | AA27: x | AB27: x | AK27: 5 | AL27: 5 | AM27: 10 | AN27: 15 | AO27: 15 | AP27: 15 | AQ27: 15 | AR27: 5 | AS27: 5 | AT27: 5 | AU27: 5 | AV27: 5 | AW27: 5 | AX27: 5 | AY27: 5 | AZ27: 10 | BA27: 15 | BB27: 15 | BC27: 15 | BD27: 15 | BE27: 15 | BF27: 10 | BG27: 10 | BH27: 5 | BP27: =SUM(AC27:BO27) -> 230 | BQ27: =BP27/60 -> 3.8333333
A28: 22 | B28: BOH | C28: Bar - Drinks | D28: Specific | E28: Daily | G28: Morning/Afternoon | H28: Các quầy chia sẻ công việc của vị trí này | K28: x | O28: x | P28: x | Q28: TC | R28: x | S28: x | T28: x | U28: x | V28: x | W28: x | X28: x | Y28: x | Z28: x | AA28: x | AB28: x | AK28: 5 | AL28: 5 | AM28: 5 | AN28: 5 | AO28: 10 | AP28: 10 | AQ28: 10 | AY28: 5 | AZ28: 5 | BA28: 15 | BB28: 15 | BC28: 15 | BD28: 15 | BE28: 15 | BF28: 15 | BP28: =SUM(AC28:BO28) -> 150 | BQ28: =BP28/60 -> 2.5
A29: 23 | B29: BOH | C29: Pack Delivery and Take out Order, Dispatch | D29: Specific | E29: Daily | G29: Morning/Afternoon | H29: Trong giờ cao điểm, Leader BOH sẽ đảm nhiệm vị trí này để kiểm soát chất lượng và thời gian | L29: x | O29: x | P29: x | Q29: TC | R29: x | S29: x | T29: x | U29: x | V29: x | W29: x | X29: x | Y29: x | Z29: x | AA29: x | AB29: x | AM29: 5 | AN29: 5 | AO29: 10 | AP29: 10 | AQ29: 10 | BA29: 15 | BB29: 15 | BC29: 15 | BD29: 15 | BE29: 10 | BF29: 10 | BP29: =SUM(AC29:BO29) -> 120 | BQ29: =BP29/60 -> 2
A30: 24 | B30: BOH | C30: Dish washing | D30: Basic | E30: Daily | F30: Flexible | G30: Morning/Afternoon | H30: Thời gian thấp điểm MOD phân công 1 nhân viên | J30: x | K30: x | L30: x | M30: x | N30: x | O30: x | P30: x | Q30: TC | R30: x | S30: x | T30: x | U30: x | V30: x | W30: x | X30: x | Y30: x | Z30: x | AA30: x | AB30: x | AQ30: 10 | AR30: 30 | AS30: 20 | AX30: 30 | BE30: 20 | BF30: 30 | BG30: 20 | BP30: =SUM(AC30:BO30) -> 160 | BQ30: =BP30/60 -> 2.6666667
A31: 25 | B31: ALL | C31: Rest room Clearning | D31: Basic | E31: Daily | F31: Flexible | G31: Morning/Afternoon | H31: Linh hoạt thời gian và PIC | AJ31: 10 | AT31: 10 | AZ31: 10 | BH31: 10
A32: 26 | B32: FOH | C32: OPENING CLEANING FOH | D32: Basic | E32: Daily | F32: Fixed | G32: Morning | N32: x | O32: x | P32: x | Q32: TC | R32: x | S32: x | T32: x | U32: x | V32: x | W32: x | X32: x | Y32: x | Z32: x | AA32: x | AB32: x | BP32: =SUM(AC32:BO32) -> 0 | BQ32: =BP32/60 -> 0
A33: 27 | B33: FOH | C33: Cleaning glasses / Signage | D33: Basic | E33: Daily | F33: Fixed | G33: Morning | H33: Nhân viên CSR sau khi đi bank với quản lý về sẽ vệ sinh kính từ 9h20 đến 9h40 | K33: x | L33: x | O33: x | P33: x | Q33: Store Area | R33: x | S33: x | T33: x | U33: x | V33: x | W33: x | X33: x | Y33: x | Z33: x | AA33: x | AB33: x | AI33: 10 | BP33: =SUM(AC33:BO33) -> 10 | BQ33: =BP33/60 -> 0.16666667
A34: 28 | B34: FOH | C34: Sweep / Mop Floor | D34: Basic | E34: Daily | F34: Flexible | G34: Morning/Afternoon | H34: Quét và lau sàn FOH đầu ca, giữa ca và đóng ca | K34: x | L34: x | O34: x | P34: x | Q34: Store Area | R34: x | S34: x | T34: x | U34: x | V34: x | W34: x | X34: x | Y34: x | Z34: x | AA34: x | AB34: x | AI34: 15 | AT34: 15 | BH34: 15 | BP34: =SUM(AC34:BO34) -> 45 | BQ34: =BP34/60 -> 0.75
A35: 29 | B35: FOH | C35: Cleaning tables, sofas, chairs,… | D35: Basic | E35: Daily | F35: Fixed | G35: Morning | H35: Nhân viên CSR sau khi đi bank với quản lý về sẽ vệ sinh kính từ 9h20 đến 9h40 | BP35: =SUM(AC35:BO35) -> 0 | BQ35: =BP35/60 -> 0
A36: 30 | B36: FOH | C36: Set-up table & Prepare dine-in condiments | D36: Basic | E36: Daily | F36: Fixed | G36: Morning | H36: Set-up theo khu vực riêng trước 10h sáng, các khu vực khác có thể hoàn thiện sau theo thực tế lượng khách buổi trưa. | L36: x | AJ36: 10 | AK36: 10 | BP36: =SUM(AC36:BO36) -> 20 | BQ36: =BP36/60 -> 0.33333333
A37: 31 | B37: FOH | C37: Prepare Delievery & Take aways condiments | D37: Basic | E37: Daily | F37: Fixed | G37: Morning | H37: Theo kế hoạch chuẩn bị hàng hóa | L37: x | AJ37: 5 | AL37: 10 | AS37: 10 | AU37: 15 | BP37: =SUM(AC37:BO37) -> 40 | BQ37: =BP37/60 -> 0.66666667
A38: 32 | B38: FOH | C38: Cashier check cashflow before opening | D38: Specific | E38: Daily | F38: Fixed | G38: Morning | H38: Quản lý bàn giao tiền cho CSR và túi bao tử, chìa khóa xe giao hàng Ký bàn gian sổ sách => hoàn thành trước 10h | J38: x | L38: x | Q38: No. of Cashier Counter | R38: x | S38: x | T38: x | U38: x | V38: x | W38: x | X38: x | Y38: x | Z38: x | AA38: x | AB38: x | AJ38: 5 | BP38: =SUM(AC38:BO38) -> 5 | BQ38: =BP38/60 -> 0.083333333
A39: 33 | B39: MGNT | C39: Breifing | D39: Specific | E39: Daily | F39: Flexible | G39: Morning/Afternoon | H39: Họp đầu thực hiện trước giờ bán hàng gồm 1 quản lý và 4-5 nhân viên (thời gian họp 5p x 6 = 30p) | I39: x | J39: x | K39: x | L39: x | M39: x | N39: x | O39: x | P39: x | Q39: TC | R39: x | S39: x | T39: x | U39: x | V39: x | W39: x | X39: x | Y39: x | Z39: x | AA39: x | AB39: x | AK39: 20 | AY39: 20 | BP39: =SUM(AC39:BO39) -> 40 | BQ39: =BP39/60 -> 0.66666667
A40: 34 | B40: FOH | C40: CSR/Cashier | D40: Specific | E40: Daily | F40: Fixed | G40: Morning/Afternoon | H40: Giờ cao điểm cần 1 nhân viên đứng độc lập 1 quầy, giờ thấp điểm kết hợp Server và Hostess | L40: x | O40: x | P40: x | Q40: TC | R40: x | S40: x | T40: x | U40: x | V40: x | W40: x | X40: x | Y40: x | Z40: x | AA40: x | AB40: x | AK40: 15 | AL40: 10 | AM40: 30 | AN40: 30 | AO40: 30 | AP40: 30 | AQ40: 30 | AR40: 30 | AS40: 20 | AT40: 20 | AU40: 15 | AV40: 15 | AW40: 15 | AX40: 15 | AY40: 30 | AZ40: 30 | BA40: 30 | BB40: 30 | BC40: 30 | BD40: 30 | BE40: 30 | BF40: 30 | BG40: 30 | BH40: 5 | BP40: =SUM(AC40:BO40) -> 580 | BQ40: =BP40/60 -> 9.6666667
...

Sheet Base Line COL
K1: AVERAGE DAY PART | O1: Trans | P1: 3 | Q1: Sales | R1: 717426 | U1: Trans | V1: 8 | X1: 2057641 | AA1: Trans | AB1: 5 | AC1: Sales | AD1: 1080194 | AG1: Trans | AH1: 22 | AI1: Sales | AJ1: 5580035 | AM1: Trans | AN1: 6 | AO1: Sales | AP1: 1445381
M2: EARLY LUNCH | U2: LUNCH | AA2: TEA | AG2: DINNER | AM2: LATE DINNER
A3: Store Name | B3: Day | C3: Base line Labor hours | D3: Estimate Sale (Maximize) | E3: Productivity | F3: Estimate COL | H3: Level | I3: Counter | J3: From | K3: To | L3: Total Hr | M3: 700 | N3: 730 | O3: 800 | P3: 830 | Q3: 900 | R3: 930 | S3: 1000 | T3: 1030 | U3: 1100 | V3: 1130 | W3: 1200 | X3: 1230 | Y3: 1300 | Z3: 1330 | AA3: 1400 | AB3: =AA4 -> 1430 | AC3: =AB4 -> 1500 | AD3: =AC4 -> 1530 | AE3: =AD4 -> 1600 | AF3: =AE4 -> 1630 | AG3: =AF4 -> 1700 | AH3: =AG4 -> 1730 | AI3: =AH4 -> 1800 | ... AS3: =AR4 -> 2300 | AT3: 2300 | AU3: NOTE
A4: Concept | M4: 730 | N4: 800 | O4: 830 | P4: 900 | Q4: 930 | R4: 1000 | S4: 1030 | T4: 1100 | U4: 1130 | V4: 1200 | W4: 1230 | X4: 1300 | Y4: 1330 | Z4: 1400 | AA4: 1430 | AB4: 1500 | AC4: 1530 | AD4: 1600 | AE4: 1630 | AF4: 1700 | AG4: 1730 | AH4: 1800 | AI4: 1830 | AJ4: 1900 | AK4: 1930 | AL4: 2000 | AM4: 2030 | AN4: 2100 | AO4: 2130 | AP4: 2200 | AQ4: 2230 | AR4: 2300 | AS4: 2330 | AT4: 2400
A5: DEMO | B5: Mon | C5: =L5 -> 70 | D5: 10000000 | E5: =+D5/C5 -> 142857.14 | H5: Total | L5: =(SUM(M5:AT5))/2 -> 70 | M5: =COUNTA(M6:M36)-COUNTIF(M6:M36,"") -> 0 | N5: =COUNTA(N6:N36)-COUNTIF(N6:N36,"") -> 0 | O5: =COUNTA(O6:O36)-COUNTIF(O6:O36,"") -> 2 | P5: =COUNTA(P6:P36)-COUNTIF(P6:P36,"") -> 2 | Q5: =COUNTA(Q6:Q36)-COUNTIF(Q6:Q36,"") -> 4 | R5: =COUNTA(R6:R36)-COUNTIF(R6:R36,"") -> 4 | S5: =COUNTA(S6:S36)-COUNTIF(S6:S36,"") -> 4 | T5: =COUNTA(T6:T36)-COUNTIF(T6:T36,"") -> 4 | ... AT5: =COUNTA(AT6:AT36)-COUNTIF(AT6:AT36,"") -> 0
A6: FCD | H6: MGNT | I6: Mngt 1 | J6: 800 | K6: 1600 | L6: =(COUNTA(M6:AT6)-COUNTIF(M6:AT6,""))/2 -> 8 | M6: =IF(AND(M$3>$J6,M$4<$K6),"-------",IF(M$3=$J6,"<-----",IF(M$4=$K6,"----->",""))) | N6: =IF(AND(N$3>$J6,N$4<$K6),"-------",IF(N$3=$J6,"<-----",IF(N$4=$K6,"----->",""))) | O6: =IF(AND(O$3>$J6,O$4<$K6),"---------",IF(O$3=$J6,"<-----",IF(O$4=$K6,"----->",""))) -> <----- | P6: =IF(AND(P$3>$J6,P$4<$K6),"-------",IF(P$3=$J6,"<-----",IF(P$4=$K6,"----->",""))) -> ------- | Q6: =IF(AND(Q$3>$J6,Q$4<$K6),"-------",IF(Q$3=$J6,"<-----",IF(Q$4=$K6,"----->",""))) -> ------- | R6: =IF(AND(R$3>$J6,R$4<$K6),"-----------",IF(R$3=$J6,"<-----",IF(R$4=$K6,"----->",""))) -> ----------- | S6: =IF(AND(S$3>$J6,S$4<$K6),"-------",IF(S$3=$J6,"<-----",IF(S$4=$K6,"----->",""))) -> ------- | T6: =IF(AND(T$3>$J6,T$4<$K6),"-------",IF(T$3=$J6,"<-----",IF(T$4=$K6,"----->",""))) -> ------- | U6: =IF(AND(U$3>$J6,U$4<$K6),"-------",IF(U$3=$J6,"<-----",IF(U$4=$K6,"----->",""))) -> ------- | V6: =IF(AND(V$3>$J6,V$4<$K6),"-------",IF(V$3=$J6,"<-----",IF(V$4=$K6,"----->",""))) -> ------- | W6: =IF(AND(W$3>$J6,W$4<$K6),"-------",IF(W$3=$J6,"<-----",IF(W$4=$K6,"----->",""))) -> ------- | X6: =IF(AND(X$3>$J6,X$4<$K6),"-----------",IF(X$3=$J6,"<-----",IF(X$4=$K6,"----->",""))) -> ----------- | Y6: =IF(AND(Y$3>$J6,Y$4<$K6),"-------",IF(Y$3=$J6,"<-----",IF(Y$4=$K6,"----->",""))) -> ------- | Z6: =IF(AND(Z$3>$J6,Z$4<$K6),"-------",IF(Z$3=$J6,"<-----",IF(Z$4=$K6,"----->",""))) -> ------- | AA6: =IF(AND(AA$3>$J6,AA$4<$K6),"-------",IF(AA$3=$J6,"<-----",IF(AA$4=$K6,"----->",""))) -> ------- | AB6: =IF(AND(AB$3>$J6,AB$4<$K6),"-------",IF(AB$3=$J6,"<-----",IF(AB$4=$K6,"----->",""))) -> ------- | AC6: =IF(AND(AC$3>$J6,AC$4<$K6),"-------",IF(AC$3=$J6,"<-----",IF(AC$4=$K6,"----->",""))) -> ------- | AD6: =IF(AND(AD$3>$J6,AD$4<$K6),"-------",IF(AD$3=$J6,"<-----",IF(AD$4=$K6,"---------->",""))) -> ----------> | AE6: =IF(AND(AE$3>$J6,AE$4<$K6),"-------",IF(AE$3=$J6,"<-----",IF(AE$4=$K6,"----->",""))) | AF6: =IF(AND(AF$3>$J6,AF$4<$K6),"-------",IF(AF$3=$J6,"<-----",IF(AF$4=$K6,"----->",""))) | AG6: =IF(AND(AG$3>$J6,AG$4<$K6),"-------",IF(AG$3=$J6,"<-----",IF(AG$4=$K6,"----->",""))) | AH6: =IF(AND(AH$3>$J6,AH$4<$K6),"-------",IF(AH$3=$J6,"<-----",IF(AH$4=$K6,"----->",""))) | AI6: =IF(AND(AI$3>$J6,AI$4<$K6),"-------",IF(AI$3=$J6,"<-----",IF(AI$4=$K6,"----->",""))) | AJ6: =IF(AND(AJ$3>$J6,AJ$4<$K6),"-------",IF(AJ$3=$J6,"<-----",IF(AJ$4=$K6,"----->",""))) | AK6: =IF(AND(AK$3>$J6,AK$4<$K6),"-------",IF(AK$3=$J6,"<-----",IF(AK$4=$K6,"----->",""))) | AL6: =IF(AND(AL$3>$J6,AL$4<$K6),"-------",IF(AL$3=$J6,"<-----",IF(AL$4=$K6,"----->",""))) | ... AT6: =IF(AND(AT$3>$J6,AT$4<$K6),"-------",IF(AT$3=$J6,"<-----",IF(AT$4=$K6,"----->","")))
A7: Grand Total | C7: =SUM(P1,V1,AB1,AG1,AN1) -> 22 | D7: =SUM(R1,X1,AD1,AJ1,AP1) -> 10880677 | I7: Mngt 2 | J7: 1500 | K7: 2300 | L7: =(COUNTA(M7:AT7)-COUNTIF(M7:AT7,""))/2 -> 8 | M7: =IF(AND(M$3>$J7,M$4<$K7),"-------",IF(M$3=$J7,"<-----",IF(M$4=$K7,"----->",""))) | N7: =IF(AND(N$3>$J7,N$4<$K7),"-------",IF(N$3=$J7,"<-----",IF(N$4=$K7,"----->",""))) | O7: =IF(AND(O$3>$J7,O$4<$K7),"-------",IF(O$3=$J7,"<-----",IF(O$4=$K7,"----->",""))) | P7: =IF(AND(P$3>$J7,P$4<$K7),"-------",IF(P$3=$J7,"<-----",IF(P$4=$K7,"----->",""))) | Q7: =IF(AND(Q$3>$J7,Q$4<$K7),"-------",IF(Q$3=$J7,"<-----",IF(Q$4=$K7,"----->",""))) | R7: =IF(AND(R$3>$J7,R$4<$K7),"-------",IF(R$3=$J7,"<-----",IF(R$4=$K7,"----->",""))) | S7: =IF(AND(S$3>$J7,S$4<$K7),"-------",IF(S$3=$J7,"<-----",IF(S$4=$K7,"----->",""))) | T7: =IF(AND(T$3>$J7,T$4<$K7),"-------",IF(T$3=$J7,"<-----",IF(T$4=$K7,"----->",""))) | ... AC7: =IF(AND(AC$3>$J7,AC$4<$K7),"-------",IF(AC$3=$J7,"<-----",IF(AC$4=$K7,"----->",""))) -> <----- | AD7: =IF(AND(AD$3>$J7,AD$4<$K7),"------------",IF(AD$3=$J7,"<-----",IF(AD$4=$K7,"----->",""))) -> ------------ | AE7: =IF(AND(AE$3>$J7,AE$4<$K7),"-------",IF(AE$3=$J7,"<-----",IF(AE$4=$K7,"----->",""))) -> ------- | AF7: =IF(AND(AF$3>$J7,AF$4<$K7),"-------",IF(AF$3=$J7,"<-----",IF(AF$4=$K7,"----->",""))) -> ------- | AG7: =IF(AND(AG$3>$J7,AG$4<$K7),"-------",IF(AG$3=$J7,"<-----",IF(AG$4=$K7,"----->",""))) -> ------- | AH7: =IF(AND(AH$3>$J7,AH$4<$K7),"-------",IF(AH$3=$J7,"<-----",IF(AH$4=$K7,"----->",""))) -> ------- | AI7: =IF(AND(AI$3>$J7,AI$4<$K7),"-------",IF(AI$3=$J7,"<-----",IF(AI$4=$K7,"----->",""))) -> ------- | AJ7: =IF(AND(AJ$3>$J7,AJ$4<$K7),"-------------",IF(AJ$3=$J7,"<-----",IF(AJ$4=$K7,"----->",""))) -> ------------- | AK7: =IF(AND(AK$3>$J7,AK$4<$K7),"-------",IF(AK$3=$J7,"<-----",IF(AK$4=$K7,"----->",""))) -> ------- | AL7: =IF(AND(AL$3>$J7,AL$4<$K7),"-------",IF(AL$3=$J7,"<-----",IF(AL$4=$K7,"----->",""))) -> ------- | AM7: =IF(AND(AM$3>$J7,AM$4<$K7),"-------",IF(AM$3=$J7,"<-----",IF(AM$4=$K7,"----->",""))) -> ------- | AN7: =IF(AND(AN$3>$J7,AN$4<$K7),"-------",IF(AN$3=$J7,"<-----",IF(AN$4=$K7,"----->",""))) -> ------- | AO7: =IF(AND(AO$3>$J7,AO$4<$K7),"-------",IF(AO$3=$J7,"<-----",IF(AO$4=$K7,"----->",""))) -> ------- | AP7: =IF(AND(AP$3>$J7,AP$4<$K7),"-------------",IF(AP$3=$J7,"<-----",IF(AP$4=$K7,"----->",""))) -> ------------- | AQ7: =IF(AND(AQ$3>$J7,AQ$4<$K7),"---------",IF(AQ$3=$J7,"<-----",IF(AQ$4=$K7,"---------->",""))) -> --------- | AR7: =IF(AND(AR$3>$J7,AR$4<$K7),"-------",IF(AR$3=$J7,"<-----",IF(AR$4=$K7,"----->",""))) -> -----> | AS7: =IF(AND(AS$3>$J7,AS$4<$K7),"-------",IF(AS$3=$J7,"<-----",IF(AS$4=$K7,"----->",""))) | AT7: =IF(AND(AT$3>$J7,AT$4<$K7),"-------",IF(AT$3=$J7,"<-----",IF(AT$4=$K7,"----->","")))
A8: Cập nhật thực tế Sales mix của store vào ô xanh dưới đây | I8: Mgnt 3 | L8: =(COUNTA(M8:AT8)-COUNTIF(M8:AT8,""))/2 -> 0 | M8: =IF(AND(M$3>$J8,M$4<$K8),"-------",IF(M$3=$J8,"<-----",IF(M$4=$K8,"----->",""))) | N8: =IF(AND(N$3>$J8,N$4<$K8),"-------",IF(N$3=$J8,"<-----",IF(N$4=$K8,"----->",""))) | O8: =IF(AND(O$3>$J8,O$4<$K8),"-------",IF(O$3=$J8,"<-----",IF(O$4=$K8,"----->",""))) | P8: =IF(AND(P$3>$J8,P$4<$K8),"-------",IF(P$3=$J8,"<-----",IF(P$4=$K8,"----->",""))) | Q8: =IF(AND(Q$3>$J8,Q$4<$K8),"-------",IF(Q$3=$J8,"<-----",IF(Q$4=$K8,"----->",""))) | R8: =IF(AND(R$3>$J8,R$4<$K8),"-------",IF(R$3=$J8,"<-----",IF(R$4=$K8,"----->",""))) | S8: =IF(AND(S$3>$J8,S$4<$K8),"-------",IF(S$3=$J8,"<-----",IF(S$4=$K8,"----->",""))) | T8: =IF(AND(T$3>$J8,T$4<$K8),"-------",IF(T$3=$J8,"<-----",IF(T$4=$K8,"----->",""))) | ... AT8: =IF(AND(AT$3>$J8,AT$4<$K8),"-------",IF(AT$3=$J8,"<-----",IF(AT$4=$K8,"----->","")))
A9: Sales mix | C9: DI | D9: TA | E9: DELI | F9: Grand Total | L9: =(COUNTA(M9:AT9)-COUNTIF(M9:AT9,""))/2 -> 0 | M9: =IF(AND(M$3>$J9,M$4<$K9),"-------",IF(M$3=$J9,"<-----",IF(M$4=$K9,"----->",""))) | N9: =IF(AND(N$3>$J9,N$4<$K9),"-------",IF(N$3=$J9,"<-----",IF(N$4=$K9,"----->",""))) | O9: =IF(AND(O$3>$J9,O$4<$K9),"-------",IF(O$3=$J9,"<-----",IF(O$4=$K9,"----->",""))) | P9: =IF(AND(P$3>$J9,P$4<$K9),"-------",IF(P$3=$J9,"<-----",IF(P$4=$K9,"----->",""))) | Q9: =IF(AND(Q$3>$J9,Q$4<$K9),"-------",IF(Q$3=$J9,"<-----",IF(Q$4=$K9,"----->",""))) | R9: =IF(AND(R$3>$J9,R$4<$K9),"-------",IF(R$3=$J9,"<-----",IF(R$4=$K9,"----->",""))) | S9: =IF(AND(S$3>$J9,S$4<$K9),"-------",IF(S$3=$J9,"<-----",IF(S$4=$K9,"----->",""))) | T9: =IF(AND(T$3>$J9,T$4<$K9),"-------",IF(T$3=$J9,"<-----",IF(T$4=$K9,"----->",""))) | ... AT9: =IF(AND(AT$3>$J9,AT$4<$K9),"-------",IF(AT$3=$J9,"<-----",IF(AT$4=$K9,"----->","")))
C10: 0.33 | D10: 0.42 | E10: 0.25 | H10: BOH | I10: Auxi/Bar 1 | J10: 1100 | K10: 1530 | L10: =(COUNTA(M10:AT10)-COUNTIF(M10:AT10,""))/2 -> 4.5 | M10: =IF(AND(M$3>$J10,M$4<$K10),"-------",IF(M$3=$J10,"<-----",IF(M$4=$K10,"----->",""))) | N10: =IF(AND(N$3>$J10,N$4<$K10),"-------",IF(N$3=$J10,"<-----",IF(N$4=$K10,"----->",""))) | O10: =IF(AND(O$3>$J10,O$4<$K10),"-------",IF(O$3=$J10,"<-----",IF(O$4=$K10,"----->",""))) | P10: =IF(AND(P$3>$J10,P$4<$K10),"-------",IF(P$3=$J10,"<-----",IF(P$4=$K10,"----->",""))) | Q10: =IF(AND(Q$3>$J10,Q$4<$K10),"-------",IF(Q$3=$J10,"<-----",IF(Q$4=$K10,"----->",""))) | R10: =IF(AND(R$3>$J10,R$4<$K10),"-------",IF(R$3=$J10,"<-----",IF(R$4=$K10,"----->",""))) | S10: =IF(AND(S$3>$J10,S$4<$K10),"-------",IF(S$3=$J10,"<-----",IF(S$4=$K10,"----->",""))) | T10: =IF(AND(T$3>$J10,T$4<$K10),"-------",IF(T$3=$J10,"<-----",IF(T$4=$K10,"----->",""))) | ... W10: =IF(AND(W$3>$J10,W$4<$K10),"-------",IF(W$3=$J10,"<-----",IF(W$4=$K10,"----->",""))) -> ------- | X10: =IF(AND(X$3>$J10,X$4<$K10),"------------",IF(X$3=$J10,"<-----",IF(X$4=$K10,"----->",""))) -> ------------ | Y10: =IF(AND(Y$3>$J10,Y$4<$K10),"-------",IF(Y$3=$J10,"<-----",IF(Y$4=$K10,"----->",""))) -> ------- | Z10: =IF(AND(Z$3>$J10,Z$4<$K10),"-------",IF(Z$3=$J10,"<-----",IF(Z$4=$K10,"----->",""))) -> ------- | AA10: =IF(AND(AA$3>$J10,AA$4<$K10),"-------",IF(AA$3=$J10,"<-----",IF(AA$4=$K10,"----->",""))) -> ------- | AB10: =IF(AND(AB$3>$J10,AB$4<$K10),"-------",IF(AB$3=$J10,"<-----",IF(AB$4=$K10,"----->",""))) -> ------- | AC10: =IF(AND(AC$3>$J10,AC$4<$K10),"-------",IF(AC$3=$J10,"<-----",IF(AC$4=$K10,"----->",""))) -> -----> | AD10: =IF(AND(AD$3>$J10,AD$4<$K10),"-------",IF(AD$3=$J10,"<-----",IF(AD$4=$K10,"----->",""))) | AE10: =IF(AND(AE$3>$J10,AE$4<$K10),"-------",IF(AE$3=$J10,"<-----",IF(AE$4=$K10,"----->",""))) | AF10: =IF(AND(AF$3>$J10,AF$4<$K10),"-------",IF(AF$3=$J10,"<-----",IF(AF$4=$K10,"----->",""))) | ... AT10: =IF(AND(AT$3>$J10,AT$4<$K10),"-------",IF(AT$3=$J10,"<-----",IF(AT$4=$K10,"----->","")))
A11: Early Lunch | B11: 0.188 | C11: =+$D$5*C$10*$B11 -> 620400 | D11: =+$D$5*D$10*$B11 -> 789600 | E11: =+$D$5*E$10*$B11 -> 470000 | F11: =SUM(C11:E11) -> 1880000 | I11: Auxi/Bar 2 | L11: =(COUNTA(M11:AT11)-COUNTIF(M11:AT11,""))/2 -> 0 | M11: =IF(AND(M$3>$J11,M$4<$K11),"-------",IF(M$3=$J11,"<-----",IF(M$4=$K11,"----->",""))) | N11: =IF(AND(N$3>$J11,N$4<$K11),"-------",IF(N$3=$J11,"<-----",IF(N$4=$K11,"----->",""))) | O11: =IF(AND(O$3>$J11,O$4<$K11),"-------",IF(O$3=$J11,"<-----",IF(O$4=$K11,"----->",""))) | P11: =IF(AND(P$3>$J11,P$4<$K11),"-------",IF(P$3=$J11,"<-----",IF(P$4=$K11,"----->",""))) | Q11: =IF(AND(Q$3>$J11,Q$4<$K11),"-------",IF(Q$3=$J11,"<-----",IF(Q$4=$K11,"----->",""))) | R11: =IF(AND(R$3>$J11,R$4<$K11),"-------",IF(R$3=$J11,"<-----",IF(R$4=$K11,"----->",""))) | S11: =IF(AND(S$3>$J11,S$4<$K11),"-------",IF(S$3=$J11,"<-----",IF(S$4=$K11,"----->",""))) | T11: =IF(AND(T$3>$J11,T$4<$K11),"-------",IF(T$3=$J11,"<-----",IF(T$4=$K11,"----->",""))) | ... AT11: =IF(AND(AT$3>$J11,AT$4<$K11),"-------",IF(AT$3=$J11,"<-----",IF(AT$4=$K11,"----->","")))
A12: Lunch | B12: 0.179 | C12: =+$D$5*C$10*$B12 -> 590700 | D12: =+$D$5*D$10*$B12 -> 751800 | E12: =+$D$5*E$10*$B12 -> 447500 | F12: =SUM(C12:E12) -> 1790000 | I12: Auxi/Bar 3 | J12: 1700 | K12: 2100 | L12: =(COUNTA(M12:AT12)-COUNTIF(M12:AT12,""))/2 -> 4 | M12: =IF(AND(M$3>$J12,M$4<$K12),"-------",IF(M$3=$J12,"<-----",IF(M$4=$K12,"----->",""))) | N12: =IF(AND(N$3>$J12,N$4<$K12),"-------",IF(N$3=$J12,"<-----",IF(N$4=$K12,"----->",""))) | O12: =IF(AND(O$3>$J12,O$4<$K12),"-------",IF(O$3=$J12,"<-----",IF(O$4=$K12,"----->",""))) | P12: =IF(AND(P$3>$J12,P$4<$K12),"-------",IF(P$3=$J12,"<-----",IF(P$4=$K12,"----->",""))) | Q12: =IF(AND(Q$3>$J12,Q$4<$K12),"-------",IF(Q$3=$J12,"<-----",IF(Q$4=$K12,"----->",""))) | R12: =IF(AND(R$3>$J12,R$4<$K12),"-------",IF(R$3=$J12,"<-----",IF(R$4=$K12,"----->",""))) | S12: =IF(AND(S$3>$J12,S$4<$K12),"-------",IF(S$3=$J12,"<-----",IF(S$4=$K12,"----->",""))) | T12: =IF(AND(T$3>$J12,T$4<$K12),"-------",IF(T$3=$J12,"<-----",IF(T$4=$K12,"----->",""))) | ... AI12: =IF(AND(AI$3>$J12,AI$4<$K12),"-------",IF(AI$3=$J12,"<-----",IF(AI$4=$K12,"----->",""))) -> ------- | AJ12: =IF(AND(AJ$3>$J12,AJ$4<$K12),"--------------",IF(AJ$3=$J12,"<-----",IF(AJ$4=$K12,"----->",""))) -> -------------- | AK12: =IF(AND(AK$3>$J12,AK$4<$K12),"-------",IF(AK$3=$J12,"<-----",IF(AK$4=$K12,"----->",""))) -> ------- | AL12: =IF(AND(AL$3>$J12,AL$4<$K12),"-------",IF(AL$3=$J12,"<-----",IF(AL$4=$K12,"----->",""))) -> ------- | AM12: =IF(AND(AM$3>$J12,AM$4<$K12),"-------",IF(AM$3=$J12,"<-----",IF(AM$4=$K12,"----->",""))) -> ------- | AN12: =IF(AND(AN$3>$J12,AN$4<$K12),"-------",IF(AN$3=$J12,"<-----",IF(AN$4=$K12,"----->",""))) -> -----> | AO12: =IF(AND(AO$3>$J12,AO$4<$K12),"-------",IF(AO$3=$J12,"<-----",IF(AO$4=$K12,"----->",""))) | AP12: =IF(AND(AP$3>$J12,AP$4<$K12),"-------",IF(AP$3=$J12,"<-----",IF(AP$4=$K12,"----->",""))) | AQ12: =IF(AND(AQ$3>$J12,AQ$4<$K12),"-------",IF(AQ$3=$J12,"<-----",IF(AQ$4=$K12,"----->",""))) | AR12: =IF(AND(AR$3>$J12,AR$4<$K12),"-------",IF(AR$3=$J12,"<-----",IF(AR$4=$K12,"----->",""))) | ... AT12: =IF(AND(AT$3>$J12,AT$4<$K12),"-------",IF(AT$3=$J12,"<-----",IF(AT$4=$K12,"----->","")))
A13: Tea | B13: 0.264 | C13: =+$D$5*C$10*$B13 -> 871200 | D13: =+$D$5*D$10*$B13 -> 1108800 | E13: =+$D$5*E$10*$B13 -> 660000 | F13: =SUM(C13:E13) -> 2640000 | I13: Make 1 | J13: 900 | K13: 1400 | L13: =(COUNTA(M13:AT13)-COUNTIF(M13:AT13,""))/2 -> 5 | M13: =IF(AND(M$3>$J13,M$4<$K13),"-------",IF(M$3=$J13,"<-----",IF(M$4=$K13,"----->",""))) | N13: =IF(AND(N$3>$J13,N$4<$K13),"-------",IF(N$3=$J13,"<-----",IF(N$4=$K13,"----->",""))) | O13: =IF(AND(O$3>$J13,O$4<$K13),"-------",IF(O$3=$J13,"<-----",IF(O$4=$K13,"----->",""))) | P13: =IF(AND(P$3>$J13,P$4<$K13),"-------",IF(P$3=$J13,"<-----",IF(P$4=$K13,"----->",""))) | Q13: =IF(AND(Q$3>$J13,Q$4<$K13),"-------",IF(Q$3=$J13,"<-----",IF(Q$4=$K13,"----->",""))) -> <----- | R13: =IF(AND(R$3>$J13,R$4<$K13),"------------",IF(R$3=$J13,"<-----",IF(R$4=$K13,"----->",""))) -> ------------ | S13: =IF(AND(S$3>$J13,S$4<$K13),"-------",IF(S$3=$J13,"<-----",IF(S$4=$K13,"----->",""))) -> ------- | T13: =IF(AND(T$3>$J13,T$4<$K13),"-------",IF(T$3=$J13,"<-----",IF(T$4=$K13,"----->",""))) -> ------- | U13: =IF(AND(U$3>$J13,U$4<$K13),"-------",IF(U$3=$J13,"<-----",IF(U$4=$K13,"----->",""))) -> ------- | V13: =IF(AND(V$3>$J13,V$4<$K13),"-------",IF(V$3=$J13,"<-----",IF(V$4=$K13,"----->",""))) -> ------- | W13: =IF(AND(W$3>$J13,W$4<$K13),"-------",IF(W$3=$J13,"<-----",IF(W$4=$K13,"----->",""))) -> ------- | X13: =IF(AND(X$3>$J13,X$4<$K13),"------------",IF(X$3=$J13,"<-----",IF(X$4=$K13,"----->",""))) -> ------------ | Y13: =IF(AND(Y$3>$J13,Y$4<$K13),"-------",IF(Y$3=$J13,"<-----",IF(Y$4=$K13,"----->",""))) -> ------- | Z13: =IF(AND(Z$3>$J13,Z$4<$K13),"-------",IF(Z$3=$J13,"<-----",IF(Z$4=$K13,"----->",""))) -> -----> | AA13: =IF(AND(AA$3>$J13,AA$4<$K13),"-------",IF(AA$3=$J13,"<-----",IF(AA$4=$K13,"----->",""))) | AB13: =IF(AND(AB$3>$J13,AB$4<$K13),"-------",IF(AB$3=$J13,"<-----",IF(AB$4=$K13,"----->",""))) | AC13: =IF(AND(AC$3>$J13,AC$4<$K13),"-------",IF(AC$3=$J13,"<-----",IF(AC$4=$K13,"----->",""))) | AD13: =IF(AND(AD$3>$J13,AD$4<$K13),"-------",IF(AD$3=$J13,"<-----",IF(AD$4=$K13,"----->",""))) | AE13: =IF(AND(AE$3>$J13,AE$4<$K13),"-------",IF(AE$3=$J13,"<-----",IF(AE$4=$K13,"----->",""))) | AF13: =IF(AND(AF$3>$J13,AF$4<$K13),"-------",IF(AF$3=$J13,"<-----",IF(AF$4=$K13,"----->",""))) | ... AT13: =IF(AND(AT$3>$J13,AT$4<$K13),"-------",IF(AT$3=$J13,"<-----",IF(AT$4=$K13,"----->","")))
